<?xml version="1.0" ?>
<!-- =================================================================================== -->
<!-- |    This document was autogenerated by xacro from iiwa14.urdf.xacro              | -->
<!-- |    EDITING THIS FILE BY HAND IS NOT RECOMMENDED                                 | -->
<!-- =================================================================================== -->
<!--|
    Copyright (C) 2019 Learning Algorithms and Systems Laboratory, EPFL, Switzerland
    Authors:  Konstantinos Chatzilygeroudis (maintainer)
              Bernardo Fichera
              Walid Amanhoud
    email:    costashatz@gmail.com
              bernardo.fichera@epfl.ch
              walid.amanhoud@epfl.ch
    Other contributors:
              Yoan Mollard (yoan@aubrune.eu)
    website:  lasa.epfl.ch

    This file is part of iiwa_ros.

    iiwa_ros is free software: you can redistribute it and/or modify
    it under the terms of the GNU General Public License as published by
    the Free Software Foundation, either version 3 of the License, or
    (at your option) any later version.

    iiwa_ros is distributed in the hope that it will be useful,
    but WITHOUT ANY WARRANTY; without even the implied warranty of
    MERCHANTABILITY or FITNESS FOR A PARTICULAR PURPOSE.  See the
    GNU General Public License for more details.

|-->
<robot name="iiwa14">
  <material name="Black">
    <color rgba="0.0 0.0 0.0 1.0"/>
  </material>
  <material name="Blue">
    <color rgba="0.0 0.0 0.8 1.0"/>
  </material>
  <material name="Green">
    <color rgba="0.0 0.8 0.0 1.0"/>
  </material>
  <material name="Grey">
    <color rgba="0.4 0.4 0.4 1.0"/>
  </material>
  <material name="Orange">
    <color rgba="1.0 0.4235294117647059 0.0392156862745098 1.0"/>
  </material>
  <material name="Brown">
    <color rgba="0.8705882352941177 0.8117647058823529 0.7647058823529411 1.0"/>
  </material>
  <material name="Red">
    <color rgba="0.8 0.0 0.0 1.0"/>
  </material>
  <material name="White">
    <color rgba="1.0 1.0 1.0 1.0"/>
  </material>
  <!-- Fix to world just for testing -->
  <link name="world"/>
  <!--joint between {parent} and link_0-->
  <joint name="world_iiwa_joint" type="fixed">
    <origin rpy="0 0 0" xyz="0 0 0"/>
    <parent link="world"/>
    <child link="iiwa_link_0"/>
  </joint>
  <link name="iiwa_link_0">
    <inertial>
      <origin rpy="0 0 0" xyz="-0.1 0 0.07"/>
      <mass value="5"/>
      <inertia ixx="0.05" ixy="0" ixz="0" iyy="0.06" iyz="0" izz="0.03"/>
    </inertial>
    <visual>
      <origin rpy="0 0 0" xyz="0 0 0"/>
      <geometry>
        <mesh filename="model://epfl-iiwa14/meshes/iiwa14/visual/link_0.obj"/>
      </geometry>
      <!-- <material name="Grey"/> -->
    </visual>
    <collision>
      <origin rpy="0 0 0" xyz="0 0 0"/>
      <geometry>
        <mesh filename="model://epfl-iiwa14/meshes/iiwa14/collision/link_0.stl"/>
      </geometry>
      <!-- <material name="Grey"/> -->
    </collision>
    <self_collision_checking>
      <origin rpy="0 0 0" xyz="0 0 0"/>
      <geometry>
        <capsule length="0.25" radius="0.15"/>
      </geometry>
    </self_collision_checking>
  </link>
  <!-- joint between link_0 and link_1 -->
  <joint name="iiwa_joint_1" type="revolute">
    <parent link="iiwa_link_0"/>
    <child link="iiwa_link_1"/>
    <origin rpy="0 0 0" xyz="0 0 0.1575"/>
    <axis xyz="0 0 1"/>
    <limit effort="320" lower="-2.9670597283903604" upper="2.9670597283903604" velocity="1.4835298641951802"/>
    <safety_controller k_position="100" k_velocity="10" soft_lower_limit="-2.8187067419708423" soft_upper_limit="2.8187067419708423"/>
    <dynamics damping="0.5"/>
  </joint>
  <link name="iiwa_link_1">
    <inertial>
      <origin rpy="0 0 0" xyz="0 -0.03 0.12"/>
      <mass value="4"/>
      <inertia ixx="0.1" ixy="0" ixz="0" iyy="0.09" iyz="0" izz="0.02"/>
    </inertial>
    <visual>
      <origin rpy="0 0 0" xyz="0 0 0"/>
      <geometry>
        <mesh filename="model://epfl-iiwa14/meshes/iiwa14/visual/link_1.obj"/>
      </geometry>
      <!-- <material name="Orange"/> -->
    </visual>
    <collision>
      <origin rpy="0 0 0" xyz="0 0 0"/>
      <geometry>
        <mesh filename="model://epfl-iiwa14/meshes/iiwa14/collision/link_1.stl"/>
      </geometry>
      <!-- <material name="Orange"/> -->
    </collision>
  </link>
  <!-- joint between link_1 and link_2 -->
  <joint name="iiwa_joint_2" type="revolute">
    <parent link="iiwa_link_1"/>
    <child link="iiwa_link_2"/>
    <origin rpy="1.5707963267948966   0 3.141592653589793" xyz="0 0 0.2025"/>
    <axis xyz="0 0 1"/>
    <limit effort="320" lower="-2.0943951023931953" upper="2.0943951023931953" velocity="1.4835298641951802"/>
    <safety_controller k_position="100" k_velocity="10" soft_lower_limit="-1.9896753472735356" soft_upper_limit="1.9896753472735356"/>
    <dynamics damping="0.5"/>
  </joint>
  <link name="iiwa_link_2">
    <inertial>
      <origin rpy="0 0 0" xyz="0.0003 0.059 0.042"/>
      <mass value="4"/>
      <inertia ixx="0.05" ixy="0" ixz="0" iyy="0.018" iyz="0" izz="0.044"/>
    </inertial>
    <visual>
      <origin rpy="0 0 0" xyz="0 0 0"/>
      <geometry>
        <mesh filename="model://epfl-iiwa14/meshes/iiwa14/visual/link_2.obj"/>
      </geometry>
      <!-- <material name="Orange"/> -->
    </visual>
    <collision>
      <origin rpy="0 0 0" xyz="0 0 0"/>
      <geometry>
        <mesh filename="model://epfl-iiwa14/meshes/iiwa14/collision/link_2.stl"/>
      </geometry>
      <!-- <material name="Orange"/> -->
    </collision>
  </link>
  <!-- joint between link_2 and link_3 -->
  <joint name="iiwa_joint_3" type="revolute">
    <parent link="iiwa_link_2"/>
    <child link="iiwa_link_3"/>
    <origin rpy="1.5707963267948966 0 3.141592653589793" xyz="0 0.2045 0"/>
    <axis xyz="0 0 1"/>
    <limit effort="176" lower="-2.9670597283903604" upper="2.9670597283903604" velocity="1.7453292519943295"/>
    <safety_controller k_position="100" k_velocity="10" soft_lower_limit="-2.8187067419708423" soft_upper_limit="2.8187067419708423"/>
    <dynamics damping="0.5"/>
  </joint>
  <link name="iiwa_link_3">
    <inertial>
      <origin rpy="0 0 0" xyz="0 0.03 0.13"/>
      <mass value="3"/>
      <inertia ixx="0.08" ixy="0" ixz="0" iyy="0.075" iyz="0" izz="0.01"/>
    </inertial>
    <visual>
      <origin rpy="0 0 0" xyz="0 0 0"/>
      <geometry>
        <mesh filename="model://epfl-iiwa14/meshes/iiwa14/visual/link_3.obj"/>
      </geometry>
      <!-- <material name="Orange"/> -->
    </visual>
    <collision>
      <origin rpy="0 0 0" xyz="0 0 0"/>
      <geometry>
        <mesh filename="model://epfl-iiwa14/meshes/iiwa14/collision/link_3.stl"/>
      </geometry>
      <!-- <material name="Orange"/> -->
    </collision>
  </link>
  <!-- joint between link_3 and link_4 -->
  <joint name="iiwa_joint_4" type="revolute">
    <parent link="iiwa_link_3"/>
    <child link="iiwa_link_4"/>
    <origin rpy="1.5707963267948966 0 0" xyz="0 0 0.2155"/>
    <axis xyz="0 0 1"/>
    <limit effort="176" lower="-2.0943951023931953" upper="2.0943951023931953" velocity="1.3089969389957472"/>
    <safety_controller k_position="100" k_velocity="10" soft_lower_limit="-1.9896753472735356" soft_upper_limit="1.9896753472735356"/>
    <dynamics damping="0.5"/>
  </joint>
  <link name="iiwa_link_4">
    <inertial>
      <origin rpy="0 0 0" xyz="0 0.067 0.034"/>
      <mass value="2.7"/>
      <inertia ixx="0.03" ixy="0" ixz="0" iyy="0.01" iyz="0" izz="0.029"/>
    </inertial>
    <visual>
      <origin rpy="0 0 0" xyz="0 0 0"/>
      <geometry>
        <mesh filename="model://epfl-iiwa14/meshes/iiwa14/visual/link_4.obj"/>
      </geometry>
      <!-- <material name="Orange"/> -->
    </visual>
    <collision>
      <origin rpy="0 0 0" xyz="0 0 0"/>
      <geometry>
        <mesh filename="model://epfl-iiwa14/meshes/iiwa14/collision/link_4.stl"/>
      </geometry>
      <!-- <material name="Orange"/> -->
    </collision>
  </link>
  <!-- joint between link_4 and link_5 -->
  <joint name="iiwa_joint_5" type="revolute">
    <parent link="iiwa_link_4"/>
    <child link="iiwa_link_5"/>
    <origin rpy="-1.5707963267948966 3.141592653589793 0" xyz="0 0.1845 0"/>
    <axis xyz="0 0 1"/>
    <limit effort="110" lower="-2.9670597283903604" upper="2.9670597283903604" velocity="2.2689280275926285"/>
    <safety_controller k_position="100" k_velocity="10" soft_lower_limit="-2.8187067419708423" soft_upper_limit="2.8187067419708423"/>
    <dynamics damping="0.5"/>
  </joint>
  <link name="iiwa_link_5">
    <inertial>
      <origin rpy="0 0 0" xyz="0.0001 0.021 0.076"/>
      <mass value="1.7"/>
      <inertia ixx="0.02" ixy="0" ixz="0" iyy="0.018" iyz="0" izz="0.005"/>
    </inertial>
    <visual>
      <origin rpy="0 0 0" xyz="0 0 0"/>
      <geometry>
        <mesh filename="model://epfl-iiwa14/meshes/iiwa14/visual/link_5.obj"/>
      </geometry>
      <!-- <material name="Orange"/> -->
    </visual>
    <collision>
      <origin rpy="0 0 0" xyz="0 0 0"/>
      <geometry>
        <mesh filename="model://epfl-iiwa14/meshes/iiwa14/collision/link_5.stl"/>
      </geometry>
      <!-- <material name="Orange"/> -->
    </collision>
  </link>
  <!-- joint between link_5 and link_6 -->
  <joint name="iiwa_joint_6" type="revolute">
    <parent link="iiwa_link_5"/>
    <child link="iiwa_link_6"/>
    <origin rpy="1.5707963267948966 0 0" xyz="0 0 0.2155"/>
    <axis xyz="0 0 1"/>
    <limit effort="40" lower="-2.0943951023931953" upper="2.0943951023931953" velocity="2.356194490192345"/>
    <safety_controller k_position="100" k_velocity="10" soft_lower_limit="-1.9896753472735356" soft_upper_limit="1.9896753472735356"/>
    <dynamics damping="0.5"/>
  </joint>
  <link name="iiwa_link_6">
    <inertial>
      <origin rpy="0 0 0" xyz="0 0.0006 0.0004"/>
      <mass value="1.8"/>
      <inertia ixx="0.005" ixy="0" ixz="0" iyy="0.0036" iyz="0" izz="0.0047"/>
    </inertial>
    <visual>
      <origin rpy="0 0 0" xyz="0 0 0"/>
      <geometry>
        <mesh filename="model://epfl-iiwa14/meshes/iiwa14/visual/link_6.obj"/>
      </geometry>
      <!-- <material name="Orange"/> -->
    </visual>
    <collision>
      <origin rpy="0 0 0" xyz="0 0 0"/>
      <geometry>
        <mesh filename="model://epfl-iiwa14/meshes/iiwa14/collision/link_6.stl"/>
      </geometry>
      <!-- <material name="Orange"/> -->
    </collision>
  </link>
  <!-- joint between link_6 and link_7 -->
  <joint name="iiwa_joint_7" type="revolute">
    <parent link="iiwa_link_6"/>
    <child link="iiwa_link_7"/>
    <origin rpy="-1.5707963267948966 3.141592653589793 0" xyz="0 0.081 0"/>
    <axis xyz="0 0 1"/>
    <limit effort="40" lower="-3.0543261909900763" upper="3.0543261909900763" velocity="2.356194490192345"/>
    <safety_controller k_position="100" k_velocity="10" soft_lower_limit="-2.901609881440573" soft_upper_limit="2.901609881440573"/>
    <dynamics damping="0.5"/>
  </joint>
  <link name="iiwa_link_7">
    <inertial>
      <origin rpy="0 0 0" xyz="0 0 0.02"/>
      <mass value="0.3"/>
      <inertia ixx="0.001" ixy="0" ixz="0" iyy="0.001" iyz="0" izz="0.001"/>
    </inertial>
    <visual>
      <origin rpy="0 0 0" xyz="0 0 0"/>
      <geometry>
        <mesh filename="model://epfl-iiwa14/meshes/iiwa14/visual/link_7.obj"/>
      </geometry>
      <!-- <material name="Grey"/> -->
    </visual>
    <collision>
      <origin rpy="0 0 0" xyz="0 0 0"/>
      <geometry>
        <mesh filename="model://epfl-iiwa14/meshes/iiwa14/collision/link_7.stl"/>
      </geometry>
      <!-- <material name="Grey"/> -->
    </collision>
  </link>

  <!-- <joint name="iiwa_joint_ee" type="fixed">
    <parent link="iiwa_link_7"/>
    <child link="iiwa_link_ee"/>
    <origin xyz="0 0 0.06" rpy="0 0 0"/>
  </joint> -->

  <joint name="iiwa_joint_ft_sensor" type="fixed">
    <parent link="iiwa_link_7"/>
    <child link="ft_sensor"/>
    <!-- TODO -->
    <origin xyz="0 0 0.059" rpy="0 0 0" />
  </joint>

  <joint name="iiwa_joint_camera_mount" type="fixed">
    <parent link="ft_sensor"/>
    <child link="bhand_palm_link"/>
    <!-- TODO -->
    <origin xyz="0 0 0.015" rpy="0 0 0"/>
  </joint>



  <!-- Load Gazebo lib and set the robot namespace -->
  <gazebo>
    <plugin filename="libgazebo_ros_control.so" name="gazebo_ros_control">
      <robotNamespace>/iiwa</robotNamespace>
      <robotSimType>iiwa_gazebo/GravityCompensationHWSim</robotSimType>
    </plugin>
  </gazebo>
  <!-- Link0 -->
  <gazebo reference="iiwa_link_0">
    <material>Gazebo/Grey</material>
    <mu1>0.2</mu1>
    <mu2>0.2</mu2>
  </gazebo>
  <!-- Link1 -->
  <gazebo reference="iiwa_link_1">
    <material>Gazebo/Orange</material>
    <mu1>0.2</mu1>
    <mu2>0.2</mu2>
  </gazebo>
  <!-- Link2 -->
  <gazebo reference="iiwa_link_2">
    <material>Gazebo/Orange</material>
    <mu1>0.2</mu1>
    <mu2>0.2</mu2>
  </gazebo>
  <!-- Link3 -->
  <gazebo reference="iiwa_link_3">
    <material>Gazebo/Orange</material>
    <mu1>0.2</mu1>
    <mu2>0.2</mu2>
  </gazebo>
  <!-- Link4 -->
  <gazebo reference="iiwa_link_4">
    <material>Gazebo/Orange</material>
    <mu1>0.2</mu1>
    <mu2>0.2</mu2>
  </gazebo>
  <!-- Link5 -->
  <gazebo reference="iiwa_link_5">
    <material>Gazebo/Orange</material>
    <mu1>0.2</mu1>
    <mu2>0.2</mu2>
  </gazebo>
  <!-- Link6 -->
  <gazebo reference="iiwa_link_6">
    <material>Gazebo/Orange</material>
    <mu1>0.2</mu1>
    <mu2>0.2</mu2>
  </gazebo>
  <!-- Link7 -->
  <gazebo reference="iiwa_link_7">
    <material>Gazebo/Grey</material>
    <mu1>0.2</mu1>
    <mu2>0.2</mu2>
  </gazebo>
  <transmission name="iiwa_tran_1">
    <robotNamespace>/iiwa</robotNamespace>
    <type>transmission_interface/SimpleTransmission</type>
    <joint name="iiwa_joint_1">
      <hardwareInterface>hardware_interface/PositionJointInterface</hardwareInterface>
    </joint>
    <actuator name="iiwa_motor_1">
      <hardwareInterface>hardware_interface/PositionJointInterface</hardwareInterface>
      <mechanicalReduction>1</mechanicalReduction>
    </actuator>
  </transmission>
  <transmission name="iiwa_tran_2">
    <robotNamespace>/iiwa</robotNamespace>
    <type>transmission_interface/SimpleTransmission</type>
    <joint name="iiwa_joint_2">
      <hardwareInterface>hardware_interface/PositionJointInterface</hardwareInterface>
    </joint>
    <actuator name="iiwa_motor_2">
      <hardwareInterface>hardware_interface/PositionJointInterface</hardwareInterface>
      <mechanicalReduction>1</mechanicalReduction>
    </actuator>
  </transmission>
  <transmission name="iiwa_tran_3">
    <robotNamespace>/iiwa</robotNamespace>
    <type>transmission_interface/SimpleTransmission</type>
    <joint name="iiwa_joint_3">
      <hardwareInterface>hardware_interface/PositionJointInterface</hardwareInterface>
    </joint>
    <actuator name="iiwa_motor_3">
      <hardwareInterface>hardware_interface/PositionJointInterface</hardwareInterface>
      <mechanicalReduction>1</mechanicalReduction>
    </actuator>
  </transmission>
  <transmission name="iiwa_tran_4">
    <robotNamespace>/iiwa</robotNamespace>
    <type>transmission_interface/SimpleTransmission</type>
    <joint name="iiwa_joint_4">
      <hardwareInterface>hardware_interface/PositionJointInterface</hardwareInterface>
    </joint>
    <actuator name="iiwa_motor_4">
      <hardwareInterface>hardware_interface/PositionJointInterface</hardwareInterface>
      <mechanicalReduction>1</mechanicalReduction>
    </actuator>
  </transmission>
  <transmission name="iiwa_tran_5">
    <robotNamespace>/iiwa</robotNamespace>
    <type>transmission_interface/SimpleTransmission</type>
    <joint name="iiwa_joint_5">
      <hardwareInterface>hardware_interface/PositionJointInterface</hardwareInterface>
    </joint>
    <actuator name="iiwa_motor_5">
      <hardwareInterface>hardware_interface/PositionJointInterface</hardwareInterface>
      <mechanicalReduction>1</mechanicalReduction>
    </actuator>
  </transmission>
  <transmission name="iiwa_tran_6">
    <robotNamespace>/iiwa</robotNamespace>
    <type>transmission_interface/SimpleTransmission</type>
    <joint name="iiwa_joint_6">
      <hardwareInterface>hardware_interface/PositionJointInterface</hardwareInterface>
    </joint>
    <actuator name="iiwa_motor_6">
      <hardwareInterface>hardware_interface/PositionJointInterface</hardwareInterface>
      <mechanicalReduction>1</mechanicalReduction>
    </actuator>
  </transmission>
  <transmission name="iiwa_tran_7">
    <robotNamespace>/iiwa</robotNamespace>
    <type>transmission_interface/SimpleTransmission</type>
    <joint name="iiwa_joint_7">
      <hardwareInterface>hardware_interface/PositionJointInterface</hardwareInterface>
    </joint>
    <actuator name="iiwa_motor_7">
      <hardwareInterface>hardware_interface/PositionJointInterface</hardwareInterface>
      <mechanicalReduction>1</mechanicalReduction>
    </actuator>
  </transmission>

  <!-- Gamma FT sensor -->
  <!-- https://github.com/fsuarez6/netft/blob/master/netft_description/urdf/ati_gamma.xacro -->
  <!-- The height (Z) of the denso-gamma coupler is 10mm -->
  <!-- The Z of the sensor is 28.6mm but the reference frame is at 14mm -->
  <!-- That's why we first translate the FT sensor 24mm -->
  <link name="ft_sensor">
    <visual>
      <origin xyz="0 0 0" rpy="0 0 0.52359877559" />
      <geometry>
        <mesh filename="model://ati-gamma/meshes/ati_gamma.stl"/>
      </geometry>
      <material name="aluminium">
        <color rgba="0.678 0.698 0.741 1.0" />
      </material>
    </visual>
    <collision>
      <origin xyz="0 0 0" rpy="0 0 0.52359877559" />
      <geometry>
        <mesh filename="model://ati-gamma/meshes/ati_gamma.stl"/>
      </geometry>
    </collision>
    <inertial>
      <origin xyz="9.396e-4  0.017  -7.545e-4" rpy="0 0 0" />
      <mass value="0.215" />
      <!-- mass: 0.255 ? from https://github.com/ubi-agni/ati_sensor_description/blob/master/robots/sensor_types.yaml#L6 -->
      <inertia ixx="1.055e-4" ixy="-7.262e-7" ixz="6.186e-6" iyy="1.7e-4" iyz="6.529e-7" izz="1.076e-4" />
    </inertial>
  </link>

  <!-- hand start -->
  <link name="bhand_palm_link">
    <inertial>
      <origin xyz="-5.1098e-005 0.0050433 0.036671"/>
      <mass value="0.50573"/>
      <inertia ixx="3.8374e-005" ixy="-5.604e-008" ixz="-4.2034e-005" iyy="0.00022405" iyz="1.3283e-007" izz="0.00020045"/>
    </inertial>
    <visual>
      <material name="WAMGrey">
        <color rgba="1 1 1 1"/>
      </material>
      <geometry>
        <mesh filename="barrett-bh8/meshes/sw_meshes/bhand/palm_fine.obj"/>
      </geometry>
    </visual>
    <!-- wrist -->
    <collision>
      <origin xyz="0 0 0.02029"/>
      <geometry>
        <cylinder length="0.042" radius="0.045"/>
      </geometry>
    </collision>
    <!-- spine -->
    <collision>
      <origin xyz="0 0.01105 0.05768"/>
      <geometry>
        <box size="0.024 0.108 0.033"/>
      </geometry>
    </collision>
    <!-- palm -->
    <collision>
      <origin xyz="0 0 0.07243"/>
      <geometry>
        <box size="0.076 0.046 0.012"/>
      </geometry>
      <surface>
        <friction>
          <ode>
            <mu>1</mu>
            <mu2>1</mu2>
          </ode>
        </friction>
      </surface>
    </collision>
    <!-- F1 knuckle -->
    <collision>
      <origin rpy="0 1.5707 0" xyz="0 0.05 0.07527"/>
      <geometry>
        <cylinder length="0.024" radius="0.015"/>
      </geometry>
    </collision>
  </link>
  <joint name="right_bhand_palm_surface_joint" type="fixed">
    <parent link="bhand_palm_link"/>
    <child link="right_bhand_palm_surface_link"/>
    <origin rpy="0 0 0" xyz="0 0 0.08"/>
    <limit effort="30" lower="0" upper="3.14159265359" velocity="5.0"/>
  </joint>
  <link name="right_bhand_palm_surface_link">
    <inertial>
      <mass value="0.00001"/>
      <inertia ixx="0.000001" ixy="0.0" ixz="0.0" iyy="0.000001" iyz="0.0" izz="0.000001"/>
    </inertial>
  </link>
  <joint name="right_bhand_grasp_joint" type="fixed">
    <parent link="bhand_palm_link"/>
    <child link="right_bhand_grasp_link"/>
    <origin rpy="0 0 0" xyz="0 0 0.12"/>
    <limit effort="30" lower="0" upper="3.14159265359" velocity="5.0"/>
  </joint>
  <link name="right_bhand_grasp_link">
    <collision>
      <!-- https://github.com/ros-planning/moveit_core/issues/158 -->
      <origin rpy="0 0 0" xyz="0 0 -0.13"/>
      <geometry>
        <sphere radius="0.001"/>
      </geometry>
    </collision>
    <inertial>
      <mass value="0.00001"/>
      <inertia ixx="0.000001" ixy="0.0" ixz="0.0" iyy="0.000001" iyz="0.0" izz="0.000001"/>
    </inertial>
  </link>
  <joint name="finger_1/prox_joint" type="revolute">
    <parent link="bhand_palm_link"/>
    <child link="finger_1/prox_link"/>
    <origin rpy="0 0 -1.57079632679" xyz="-0.025 0.0 0.0415"/>
    <axis xyz="0 0 -1"/>
    <limit effort="5" lower="0" upper="3.14159265359" velocity="10.0"/>
    <!-- <dynamics damping="0.35" friction="0"/> -->
    <dynamics damping="0.01" friction="0"/>
  </joint>
  <link name="finger_1/prox_link">
    <inertial>
      <origin xyz="0.023133 0.00078642 0.00052792"/>
      <mass value="0.14109"/>
      <inertia ixx="4.872e-006" ixy="1.7103e-006" ixz="3.4041e-008" iyy="7.6588e-005" iyz="2.3133e-008" izz="7.7733e-005"/>
    </inertial>
    <visual>
      <material name="WAMGrey">
        <color rgba="1 1 1 1"/>
      </material>
      <geometry>
        <mesh filename="barrett-bh8/meshes/sw_meshes/bhand/prox_fine.obj"/>
      </geometry>
    </visual>
    <!-- base -->
    <collision>
      <origin xyz="0.03217 0.0 0.01674"/>
      <geometry>
        <box size="0.066 0.024 0.033"/>
      </geometry>
    </collision>
    <!-- F2/F3 knuckle -->
    <collision>
      <origin rpy="1.5707 0 0" xyz="0.05 0.0 0.034"/>
      <geometry>
        <cylinder length="0.024" radius="0.015"/>
      </geometry>
    </collision>
  </link>
  <joint name="finger_1/med_joint" type="revolute">
    <parent link="finger_1/prox_link"/>
    <child link="finger_1/med_link"/>
    <origin rpy="1.57079632679 0 0" xyz="0.05 0.0 0.03390"/>
    <axis xyz="0 0 1"/>
    <limit effort="30" lower="0" upper="2.44346095279" velocity="10.00"/>
    <!-- <dynamics damping="0.35" friction="0"/> -->
    <dynamics damping="0.01" friction="0"/>
  </joint>
  <link name="finger_1/med_link">
    <inertial>
      <origin xyz="0.023133 0.00078642 0.00052792"/>
      <mass value="0.062139"/>
      <inertia ixx="4.872e-006" ixy="1.7103e-006" ixz="3.4041e-008" iyy="7.6588e-005" iyz="2.3133e-008" izz="7.7733e-005"/>
    </inertial>
    <visual>
      <material name="WAMGrey">
        <color rgba="1 1 1 1"/>
      </material>
      <geometry>
        <mesh filename="barrett-bh8/meshes/sw_meshes/bhand/med_fine.obj"/>
      </geometry>
    </visual>
    <!-- spine -->
    <collision>
      <origin xyz="0.03493 0.003 -0.0007"/>
      <geometry>
        <box size="0.07 0.019 0.006"/>
      </geometry>
    </collision>
    <!-- protrusion -->
    <collision>
      <origin xyz="0.03894 0.00376 -0.0007"/>
      <geometry>
        <box size="0.031 0.023 0.019"/>
      </geometry>
      <surface>
        <friction>
          <ode>
            <mu>1</mu>
            <mu2>1</mu2>
          </ode>
        </friction>
      </surface>
    </collision>
  </link>
  <joint name="finger_1/dist_joint" type="revolute">
    <parent link="finger_1/med_link"/>
    <child link="finger_1/dist_link"/>
    <origin rpy="0 0 0.785398163397" xyz="0.06994 0.003 0.0"/>
    <axis xyz="0 0 1"/>
    <limit effort="30" lower="0" upper="0.837758040957" velocity="10.00"/>
    <!-- <dynamics damping="0.35" friction="0"/> -->
    <dynamics damping="0.01" friction="0"/>
  </joint>
  <link name="finger_1/dist_link">
    <inertial>
      <origin rpy="0 0 0" xyz="0.022825 0.0010491 0.0004203"/>
      <mass value="0.041377"/>
      <inertia ixx="3.1582e-006" ixy="1.4308e-006" ixz="1.0106e-007" iyy="3.8376e-005" iyz="0" izz="3.7275e-005"/>
    </inertial>
    <visual>
      <origin rpy="0 0 -0.785398163397"/>
      <material name="WAMGrey">
        <color rgba="1 1 1 1"/>
      </material>
      <geometry>
        <mesh filename="barrett-bh8/meshes/sw_meshes/bhand/dist_fine.obj"/>
      </geometry>
    </visual>
    <collision>
      <origin rpy="0 0 -0.785398163397"/>
      <geometry>
        <mesh filename="barrett-bh8/meshes/sw_meshes/bhand/bhand_finger_dist_link_convex.dae"/>
      </geometry>
      <surface>
        <friction>
          <ode>
            <mu>1</mu>
            <mu2>1</mu2>
          </ode>
        </friction>
      </surface>
    </collision>
  </link>
  <joint name="finger_1/tip_joint" type="fixed">
    <parent link="finger_1/dist_link"/>
    <child link="finger_1/tip_link"/>
    <origin rpy="0 0 0" xyz="0.05 0.0 0.0"/>
  </joint>
  <link name="finger_1/tip_link">
    <inertial>
      <mass value="1E-6"/>
      <inertia ixx="1E-6" ixy="0" ixz="0" iyy="1E-6" iyz="0" izz="1E-6"/>
    </inertial>
  </link>
  <joint name="finger_2/prox_joint" type="revolute">
    <parent link="bhand_palm_link"/>
    <child link="finger_2/prox_link"/>
    <origin rpy="0 0 -1.57079632679" xyz="0.025 0.0 0.0415"/>
    <axis xyz="0 0 1"/>
    <limit effort="5" lower="0" upper="3.14159265359" velocity="10.0"/>
    <!-- Change the damping to influence the spread behavior -->
    <!-- <dynamics damping="0.35" friction="0"/> -->
    <dynamics damping="0.01" friction="0"/>
  </joint>
  <link name="finger_2/prox_link">
    <inertial>
      <origin xyz="0.023133 0.00078642 0.00052792"/>
      <mass value="0.14109"/>
      <inertia ixx="4.872e-006" ixy="1.7103e-006" ixz="3.4041e-008" iyy="7.6588e-005" iyz="2.3133e-008" izz="7.7733e-005"/>
    </inertial>
    <visual>
      <material name="WAMGrey">
        <color rgba="1 1 1 1"/>
      </material>
      <geometry>
        <mesh filename="barrett-bh8/meshes/sw_meshes/bhand/prox_fine.obj"/>
      </geometry>
    </visual>
    <!-- base -->
    <collision>
      <origin xyz="0.03217 0.0 0.01674"/>
      <geometry>
        <box size="0.066 0.024 0.033"/>
      </geometry>
    </collision>
    <!-- F2/F3 knuckle -->
    <collision>
      <origin rpy="1.5707 0 0" xyz="0.05 0.0 0.034"/>
      <geometry>
        <cylinder length="0.024" radius="0.015"/>
      </geometry>
    </collision>
  </link>
  <joint name="finger_2/med_joint" type="revolute">
    <parent link="finger_2/prox_link"/>
    <child link="finger_2/med_link"/>
    <origin rpy="1.57079632679 0 0" xyz="0.05 0.0 0.03390"/>
    <axis xyz="0 0 1"/>
    <limit effort="30" lower="0" upper="2.44346095279" velocity="10.00"/>
    <!-- <dynamics damping="0.35" friction="0"/> -->
    <dynamics damping="0.01" friction="0"/>
  </joint>
  <link name="finger_2/med_link">
    <inertial>
      <origin xyz="0.023133 0.00078642 0.00052792"/>
      <mass value="0.062139"/>
      <inertia ixx="4.872e-006" ixy="1.7103e-006" ixz="3.4041e-008" iyy="7.6588e-005" iyz="2.3133e-008" izz="7.7733e-005"/>
    </inertial>
    <visual>
      <material name="WAMGrey">
        <color rgba="1 1 1 1"/>
      </material>
      <geometry>
        <mesh filename="barrett-bh8/meshes/sw_meshes/bhand/med_fine.obj"/>
      </geometry>
    </visual>
    <!-- spine -->
    <collision>
      <origin xyz="0.03493 0.003 -0.0007"/>
      <geometry>
        <box size="0.07 0.019 0.006"/>
      </geometry>
    </collision>
    <!-- protrusion -->
    <collision>
      <origin xyz="0.03894 0.00376 -0.0007"/>
      <geometry>
        <box size="0.031 0.023 0.019"/>
      </geometry>
      <surface>
        <friction>
          <ode>
            <mu>1</mu>
            <mu2>1</mu2>
          </ode>
        </friction>
      </surface>
    </collision>
  </link>
  <joint name="finger_2/dist_joint" type="revolute">
    <parent link="finger_2/med_link"/>
    <child link="finger_2/dist_link"/>
    <origin rpy="0 0 0.785398163397" xyz="0.06994 0.003 0.0"/>
    <axis xyz="0 0 1"/>
    <limit effort="30" lower="0" upper="0.837758040957" velocity="10.00"/>
    <!-- <dynamics damping="0.35" friction="0"/> -->
    <dynamics damping="0.01" friction="0"/>
  </joint>
  <link name="finger_2/dist_link">
    <inertial>
      <origin rpy="0 0 0" xyz="0.022825 0.0010491 0.0004203"/>
      <mass value="0.041377"/>
      <inertia ixx="3.1582e-006" ixy="1.4308e-006" ixz="1.0106e-007" iyy="3.8376e-005" iyz="0" izz="3.7275e-005"/>
    </inertial>
    <visual>
      <origin rpy="0 0 -0.785398163397"/>
      <material name="WAMGrey">
        <color rgba="1 1 1 1"/>
      </material>
      <geometry>
        <mesh filename="barrett-bh8/meshes/sw_meshes/bhand/dist_fine.obj"/>
      </geometry>
    </visual>
    <collision>
      <origin rpy="0 0 -0.785398163397"/>
      <geometry>
        <mesh filename="barrett-bh8/meshes/sw_meshes/bhand/bhand_finger_dist_link_convex.dae"/>
      </geometry>
      <surface>
        <friction>
          <ode>
            <mu>1</mu>
            <mu2>1</mu2>
          </ode>
        </friction>
      </surface>
    </collision>
  </link>
  <joint name="finger_2/tip_joint" type="fixed">
    <parent link="finger_2/dist_link"/>
    <child link="finger_2/tip_link"/>
    <origin rpy="0 0 0" xyz="0.05 0.0 0.0"/>
  </joint>
  <link name="finger_2/tip_link">
    <inertial>
      <mass value="1E-6"/>
      <inertia ixx="1E-6" ixy="0" ixz="0" iyy="1E-6" iyz="0" izz="1E-6"/>
    </inertial>
  </link>
  <joint name="finger_3/med_joint" type="revolute">
    <parent link="bhand_palm_link"/>
    <child link="finger_3/med_link"/>
    <origin rpy="1.57079632679 0 1.57079632679" xyz="0 0.05 0.0754"/>
    <axis xyz="0 0 1"/>
    <limit effort="30" lower="0" upper="2.44346095279" velocity="10.00"/>
    <!-- <dynamics damping="0.35" friction="0"/> -->
    <dynamics damping="0.01" friction="0"/>
  </joint>
  <link name="finger_3/med_link">
    <inertial>
      <origin xyz="0.023133 0.00078642 0.00052792"/>
      <mass value="0.062139"/>
      <inertia ixx="4.872e-006" ixy="1.7103e-006" ixz="3.4041e-008" iyy="7.6588e-005" iyz="2.3133e-008" izz="7.7733e-005"/>
    </inertial>
    <visual>
      <material name="WAMGrey">
        <color rgba="1 1 1 1"/>
      </material>
      <geometry>
        <mesh filename="barrett-bh8/meshes/sw_meshes/bhand/med_fine.obj"/>
      </geometry>
    </visual>
    <!-- spine -->
    <collision>
      <origin xyz="0.03493 0.003 -0.0007"/>
      <geometry>
        <box size="0.07 0.019 0.006"/>
      </geometry>
    </collision>
    <!-- protrusion -->
    <collision>
      <origin xyz="0.03894 0.00376 -0.0007"/>
      <geometry>
        <box size="0.031 0.023 0.019"/>
      </geometry>
      <surface>
        <friction>
          <ode>
            <mu>1</mu>
            <mu2>1</mu2>
          </ode>
        </friction>
      </surface>
    </collision>
  </link>
  <joint name="finger_3/dist_joint" type="revolute">
    <parent link="finger_3/med_link"/>
    <child link="finger_3/dist_link"/>
    <origin rpy="0 0 0.785398163397" xyz="0.06994 0.003 0.0"/>
    <axis xyz="0 0 1"/>
    <limit effort="30" lower="0" upper="0.837758040957" velocity="10.00"/>
    <!-- <dynamics damping="0.35" friction="0"/> -->
    <dynamics damping="0.01" friction="0"/>
  </joint>
  <link name="finger_3/dist_link">
    <inertial>
      <origin rpy="0 0 0" xyz="0.022825 0.0010491 0.0004203"/>
      <mass value="0.041377"/>
      <inertia ixx="3.1582e-006" ixy="1.4308e-006" ixz="1.0106e-007" iyy="3.8376e-005" iyz="0" izz="3.7275e-005"/>
    </inertial>
    <visual>
      <origin rpy="0 0 -0.785398163397"/>
      <material name="WAMGrey">
        <color rgba="1 1 1 1"/>
      </material>
      <geometry>
        <mesh filename="barrett-bh8/meshes/sw_meshes/bhand/dist_fine.obj"/>
      </geometry>
    </visual>
    <collision>
      <origin rpy="0 0 -0.785398163397"/>
      <geometry>
        <mesh filename="barrett-bh8/meshes/sw_meshes/bhand/bhand_finger_dist_link_convex.dae"/>
      </geometry>
      <surface>
        <friction>
          <ode>
            <mu>1</mu>
            <mu2>1</mu2>
          </ode>
        </friction>
      </surface>
    </collision>
  </link>
  <joint name="finger_3/tip_joint" type="fixed">
    <parent link="finger_3/dist_link"/>
    <child link="finger_3/tip_link"/>
    <origin rpy="0 0 0" xyz="0.05 0.0 0.0"/>
  </joint>
  <link name="finger_3/tip_link">
    <inertial>
      <mass value="1E-6"/>
      <inertia ixx="1E-6" ixy="0" ixz="0" iyy="1E-6" iyz="0" izz="1E-6"/>
    </inertial>
  </link>
<!-- hand end -->

  
</robot>

